Workbook

Sheet DATI CLIENTE
C2: 2026_Ottobre_21
C5: Nuova richiesta / Ampliamento | G5: =IF(E5="NUOVO CLIENTE","Da valorizzare se si richiedono prodotti per clienti di nuova acquisizione",IF(E5="AMPLIAMENTO","Da valorizzare se si richiede ampliamento listino non presente in CB o listino in CB con pricing differente",IF(E5="AMPLIAMENTO MEDESIME CONDIZIONI","Da valorizzare se si richiede ampliamento listino presente in CB con medesimo pricing","")))
C6: Pubblica Amministrazione
C9: CLIENTE
C11: P.IVA | G11: =IF(E11="","",IF(LEN(E11)=11,"PIVA corretta","PIVA errata"))
C12: Ragione Sociale
C13: Trattativa Convergente Fisso/Mobile | G13: =IF(E13="SI","Valorizzare SI solo se trattativa convergente","")
C15: Canale di Vendita SME
C17: Canale di Vendita SME
C18: Nome Agenzie/Agente
C22: Canale di Vendita TELESELLER
C24: Canale di Vendita Teleseller
C25: Contratto Vendita Teleseller
C26: Nome Teleseller

Sheet OFFERTA
B2: Offerta Commerciale | J2: Promo SVO Fuori Standard | N2: Terminali | T2: UT Attivazione
B4: LISTINO | C4: N° SIM | D4: Canone mensile (€/mese/cad.) *** | E4: Secure Web Mobile | F4: MNP | G4: Operatore | H4: Promo Rimborso penali | J4: ID PROMO | K4: NOME PROMO | M4: N° terminali | N4: Modello Device | O4: Promo | P4: Rata Iniziale | Q4: Rata Mensile | R4: Rata Finale | U4: ID Promo UT Attivazione | V4: Promo UT Attivazione
E5: =IF($B5="Super Unlimited",1,IF($B5="Super Unlimited Plus",1,IF($B5="Super Smart 100GB",1,IF($B5="SUPER FLEX",1,IF($B5="SUPER GIGA 70",1,IF($B5="SUPER GIGA UNLIMITED",1,IF($B5="Super Unlimited MONDO",1,IF($B5="Super Unlimited PRO",1,IF($B5="Super Smart 200GB",1,IF($B5="Super Smart 20GB",1,0)))))))))) -> 0 | J5: =IF(ISERROR(IF(B5="","",VLOOKUP($X5,'PROMO MV SVO PER FS'!$E:$I,5,0))),"",IF(B5="","",VLOOKUP($X5,'PROMO MV SVO PER FS'!$E:$I,5,0))) | K5: =IF(ISERROR(IF(B5="","",VLOOKUP($X5,'PROMO MV SVO PER FS'!$E:$I,4,0))),"Gestita con procedura FS da CO",IF(B5="","",VLOOKUP($X5,'PROMO MV SVO PER FS'!$E:$I,4,0))) | M5: 0 | T5: FALSE | U5: =IF($T5=TRUE,IF(B5="SUPER Unlimited MONDO","9991790945508228",IF(B5="SUPER Unlimited PRO","9991790945508228",IF(B5="SUPER Smart 200GB","9991790945508228",IF(B5="Super Smart 20GB","9991790945508228",IF($B5="SUPER GIGA UNLIMITED","9991744383690315",IF($B5="SUPER GIGA 70","9991744383690315",IF($B5="SUPER GIGA 30","9991744383690315",IF($B5="M2M Full","9991761657929872")))))))),"") | V5: =IF(U5="","",IF(U5="9991790945508228","SVO - Sconto 100% Una Tantum SUPER - PROMOaVOLUME",IF(U5="9991744383305294","SVO - SCONTO 100% UNA TANTUM PRE - PROMOaVOLUME",IF(U5="9991744383690315","SVO - SCONTO 100% UNA TANTUM POST - PROMOaVOLUME",IF(U5="9991761657929872","SVO - SCONTO 100% UNA TANTUM M2M Full - PROMOaVOLUMEE"))))) | X5: =B5&"-"&D5 -> -
E6: =IF($B6="Super Unlimited",1,IF($B6="Super Unlimited Plus",1,IF($B6="Super Smart 100GB",1,IF($B6="SUPER FLEX",1,IF($B6="SUPER GIGA 70",1,IF($B6="SUPER GIGA UNLIMITED",1,IF($B6="Super Unlimited MONDO",1,IF($B6="Super Unlimited PRO",1,IF($B6="Super Smart 200GB",1,IF($B6="Super Smart 20GB",1,0)))))))))) -> 0 | J6: =IF(ISERROR(IF(B6="","",VLOOKUP($X6,'PROMO MV SVO PER FS'!$E:$I,5,0))),"",IF(B6="","",VLOOKUP($X6,'PROMO MV SVO PER FS'!$E:$I,5,0))) | K6: =IF(ISERROR(IF(B6="","",VLOOKUP($X6,'PROMO MV SVO PER FS'!$E:$I,4,0))),"Gestita con procedura FS da CO",IF(B6="","",VLOOKUP($X6,'PROMO MV SVO PER FS'!$E:$I,4,0))) | T6: FALSE | U6: =IF($T6=TRUE,IF(B6="SUPER Unlimited MONDO","9991790945508228",IF(B6="SUPER Unlimited PRO","9991790945508228",IF(B6="SUPER Smart 200GB","9991790945508228",IF(B6="Super Smart 20GB","9991790945508228",IF($B6="SUPER GIGA UNLIMITED","9991744383690315",IF($B6="SUPER GIGA 70","9991744383690315",IF($B6="SUPER GIGA 30","9991744383690315",IF($B6="M2M Full","9991761657929872")))))))),"") | V6: =IF(U6="","",IF(U6="9991790945508228","SVO - Sconto 100% Una Tantum SUPER - PROMOaVOLUME",IF(U6="9991744383305294","SVO - SCONTO 100% UNA TANTUM PRE - PROMOaVOLUME",IF(U6="9991744383690315","SVO - SCONTO 100% UNA TANTUM POST - PROMOaVOLUME",IF(U6="9991761657929872","SVO - SCONTO 100% UNA TANTUM M2M Full - PROMOaVOLUMEE"))))) | X6: =B6&"-"&D6 -> -
E7: =IF($B7="Super Unlimited",1,IF($B7="Super Unlimited Plus",1,IF($B7="Super Smart 100GB",1,IF($B7="SUPER FLEX",1,IF($B7="SUPER GIGA 70",1,IF($B7="SUPER GIGA UNLIMITED",1,IF($B7="Super Unlimited MONDO",1,IF($B7="Super Unlimited PRO",1,IF($B7="Super Smart 200GB",1,IF($B7="Super Smart 20GB",1,0)))))))))) -> 0 | J7: =IF(ISERROR(IF(B7="","",VLOOKUP($X7,'PROMO MV SVO PER FS'!$E:$I,5,0))),"",IF(B7="","",VLOOKUP($X7,'PROMO MV SVO PER FS'!$E:$I,5,0))) | K7: =IF(ISERROR(IF(B7="","",VLOOKUP($X7,'PROMO MV SVO PER FS'!$E:$I,4,0))),"Gestita con procedura FS da CO",IF(B7="","",VLOOKUP($X7,'PROMO MV SVO PER FS'!$E:$I,4,0))) | T7: FALSE | U7: =IF($T7=TRUE,IF(B7="SUPER Unlimited MONDO","9991790945508228",IF(B7="SUPER Unlimited PRO","9991790945508228",IF(B7="SUPER Smart 200GB","9991790945508228",IF(B7="Super Smart 20GB","9991790945508228",IF($B7="SUPER GIGA UNLIMITED","9991744383690315",IF($B7="SUPER GIGA 70","9991744383690315",IF($B7="SUPER GIGA 30","9991744383690315",IF($B7="M2M Full","9991761657929872")))))))),"") | V7: =IF(U7="","",IF(U7="9991790945508228","SVO - Sconto 100% Una Tantum SUPER - PROMOaVOLUME",IF(U7="9991744383305294","SVO - SCONTO 100% UNA TANTUM PRE - PROMOaVOLUME",IF(U7="9991744383690315","SVO - SCONTO 100% UNA TANTUM POST - PROMOaVOLUME",IF(U7="9991761657929872","SVO - SCONTO 100% UNA TANTUM M2M Full - PROMOaVOLUMEE"))))) | X7: =B7&"-"&D7 -> -
E8: =IF($B8="Super Unlimited",1,IF($B8="Super Unlimited Plus",1,IF($B8="Super Smart 100GB",1,IF($B8="SUPER FLEX",1,IF($B8="SUPER GIGA 70",1,IF($B8="SUPER GIGA UNLIMITED",1,IF($B8="Super Unlimited MONDO",1,IF($B8="Super Unlimited PRO",1,IF($B8="Super Smart 200GB",1,IF($B8="Super Smart 20GB",1,0)))))))))) -> 0 | J8: =IF(ISERROR(IF(B8="","",VLOOKUP($X8,'PROMO MV SVO PER FS'!$E:$I,5,0))),"",IF(B8="","",VLOOKUP($X8,'PROMO MV SVO PER FS'!$E:$I,5,0))) | K8: =IF(ISERROR(IF(B8="","",VLOOKUP($X8,'PROMO MV SVO PER FS'!$E:$I,4,0))),"Gestita con procedura FS da CO",IF(B8="","",VLOOKUP($X8,'PROMO MV SVO PER FS'!$E:$I,4,0))) | T8: FALSE | U8: =IF($T8=TRUE,IF(B8="SUPER Unlimited MONDO","9991790945508228",IF(B8="SUPER Unlimited PRO","9991790945508228",IF(B8="SUPER Smart 200GB","9991790945508228",IF(B8="Super Smart 20GB","9991790945508228",IF($B8="SUPER GIGA UNLIMITED","9991744383690315",IF($B8="SUPER GIGA 70","9991744383690315",IF($B8="SUPER GIGA 30","9991744383690315",IF($B8="M2M Full","9991761657929872")))))))),"") | V8: =IF(U8="","",IF(U8="9991790945508228","SVO - Sconto 100% Una Tantum SUPER - PROMOaVOLUME",IF(U8="9991744383305294","SVO - SCONTO 100% UNA TANTUM PRE - PROMOaVOLUME",IF(U8="9991744383690315","SVO - SCONTO 100% UNA TANTUM POST - PROMOaVOLUME",IF(U8="9991761657929872","SVO - SCONTO 100% UNA TANTUM M2M Full - PROMOaVOLUMEE"))))) | X8: =B8&"-"&D8 -> -
E9: =IF($B9="Super Unlimited",1,IF($B9="Super Unlimited Plus",1,IF($B9="Super Smart 100",1,IF($B9="SUPER FLEX",1,IF($B9="SUPER GIGA 70",1,IF($B9="SUPER GIGA UNLIMITED",1,IF($B9="Super Unlimited MONDO",1,IF($B9="Super Unlimited PRO",1,IF($B9="Super Smart 200GB",1,IF($B9="Super Smart 20GB",1,0)))))))))) -> 0 | J9: =IF(ISERROR(IF(B9="","",VLOOKUP($X9,'PROMO MV SVO PER FS'!$E:$I,5,0))),"",IF(B9="","",VLOOKUP($X9,'PROMO MV SVO PER FS'!$E:$I,5,0))) | K9: =IF(ISERROR(IF(B9="","",VLOOKUP($X9,'PROMO MV SVO PER FS'!$E:$I,4,0))),"Gestita con procedura FS da CO",IF(B9="","",VLOOKUP($X9,'PROMO MV SVO PER FS'!$E:$I,4,0))) | T9: FALSE | U9: =IF($T9=TRUE,IF(B9="SUPER Unlimited MONDO","9991790945508228",IF(B9="SUPER Unlimited PRO","9991790945508228",IF(B9="SUPER Smart 200GB","9991790945508228",IF(B9="Super Smart 20GB","9991790945508228",IF($B9="SUPER GIGA UNLIMITED","9991744383690315",IF($B9="SUPER GIGA 70","9991744383690315",IF($B9="SUPER GIGA 30","9991744383690315",IF($B9="M2M Full","9991761657929872")))))))),"") | V9: =IF(U9="","",IF(U9="9991790945508228","SVO - Sconto 100% Una Tantum SUPER - PROMOaVOLUME",IF(U9="9991744383305294","SVO - SCONTO 100% UNA TANTUM PRE - PROMOaVOLUME",IF(U9="9991744383690315","SVO - SCONTO 100% UNA TANTUM POST - PROMOaVOLUME",IF(U9="9991761657929872","SVO - SCONTO 100% UNA TANTUM M2M Full - PROMOaVOLUMEE"))))) | X9: =B9&"-"&D9 -> -
E10: =IF($B10="Super Unlimited",1,IF($B10="Super Unlimited Plus",1,IF($B10="Super Smart 100GB",1,IF($B10="SUPER FLEX",1,IF($B10="SUPER GIGA 70",1,IF($B10="SUPER GIGA UNLIMITED",1,IF($B10="Super Unlimited MONDO",1,IF($B10="Super Unlimited PRO",1,IF($B10="Super Smart 200GB",1,IF($B10="Super Smart 20GB",1,0)))))))))) -> 0 | J10: =IF(ISERROR(IF(B10="","",VLOOKUP($X10,'PROMO MV SVO PER FS'!$E:$I,5,0))),"",IF(B10="","",VLOOKUP($X10,'PROMO MV SVO PER FS'!$E:$I,5,0))) | K10: =IF(ISERROR(IF(B10="","",VLOOKUP($X10,'PROMO MV SVO PER FS'!$E:$I,4,0))),"Gestita con procedura FS da CO",IF(B10="","",VLOOKUP($X10,'PROMO MV SVO PER FS'!$E:$I,4,0))) | T10: FALSE | U10: =IF($T10=TRUE,IF(B10="SUPER Unlimited MONDO","9991790945508228",IF(B10="SUPER Unlimited PRO","9991790945508228",IF(B10="SUPER Smart 200GB","9991790945508228",IF(B10="Super Smart 20GB","9991790945508228",IF($B10="SUPER GIGA UNLIMITED","9991744383690315",IF($B10="SUPER GIGA 70","9991744383690315",IF($B10="SUPER GIGA 30","9991744383690315",IF($B10="M2M Full","9991761657929872")))))))),"") | V10: =IF(U10="","",IF(U10="9991790945508228","SVO - Sconto 100% Una Tantum SUPER - PROMOaVOLUME",IF(U10="9991744383305294","SVO - SCONTO 100% UNA TANTUM PRE - PROMOaVOLUME",IF(U10="9991744383690315","SVO - SCONTO 100% UNA TANTUM POST - PROMOaVOLUME",IF(U10="9991761657929872","SVO - SCONTO 100% UNA TANTUM M2M Full - PROMOaVOLUMEE"))))) | X10: =B10&"-"&D10 -> -
E11: =IF($B11="Super Unlimited",1,IF($B11="Super Unlimited Plus",1,IF($B11="Super Smart 100GB",1,IF($B11="SUPER FLEX",1,IF($B11="SUPER GIGA 70",1,IF($B11="SUPER GIGA UNLIMITED",1,IF($B11="Super Unlimited MONDO",1,IF($B11="Super Unlimited PRO",1,IF($B11="Super Smart 200GB",1,IF($B11="Super Smart 20GB",1,0)))))))))) -> 0 | J11: =IF(ISERROR(IF(B11="","",VLOOKUP($X11,'PROMO MV SVO PER FS'!$E:$I,5,0))),"",IF(B11="","",VLOOKUP($X11,'PROMO MV SVO PER FS'!$E:$I,5,0))) | K11: =IF(ISERROR(IF(B11="","",VLOOKUP($X11,'PROMO MV SVO PER FS'!$E:$I,4,0))),"Gestita con procedura FS da CO",IF(B11="","",VLOOKUP($X11,'PROMO MV SVO PER FS'!$E:$I,4,0))) | T11: FALSE | U11: =IF($T11=TRUE,IF(B11="SUPER Unlimited MONDO","9991790945508228",IF(B11="SUPER Unlimited PRO","9991790945508228",IF(B11="SUPER Smart 200GB","9991790945508228",IF(B11="Super Smart 20GB","9991790945508228",IF($B11="SUPER GIGA UNLIMITED","9991744383690315",IF($B11="SUPER GIGA 70","9991744383690315",IF($B11="SUPER GIGA 30","9991744383690315",IF($B11="M2M Full","9991761657929872")))))))),"") | V11: =IF(U11="","",IF(U11="9991790945508228","SVO - Sconto 100% Una Tantum SUPER - PROMOaVOLUME",IF(U11="9991744383305294","SVO - SCONTO 100% UNA TANTUM PRE - PROMOaVOLUME",IF(U11="9991744383690315","SVO - SCONTO 100% UNA TANTUM POST - PROMOaVOLUME",IF(U11="9991761657929872","SVO - SCONTO 100% UNA TANTUM M2M Full - PROMOaVOLUMEE"))))) | X11: =B11&"-"&D11 -> -
E12: =IF($B12="Super Unlimited",1,IF($B12="Super Unlimited Plus",1,IF($B12="Super Smart 100GB",1,IF($B12="SUPER FLEX",1,IF($B12="SUPER GIGA 70",1,IF($B12="SUPER GIGA UNLIMITED",1,IF($B12="Super Unlimited MONDO",1,IF($B12="Super Unlimited PRO",1,IF($B12="Super Smart 200GB",1,IF($B12="Super Smart 20GB",1,0)))))))))) -> 0 | J12: =IF(ISERROR(IF(B12="","",VLOOKUP($X12,'PROMO MV SVO PER FS'!$E:$I,5,0))),"",IF(B12="","",VLOOKUP($X12,'PROMO MV SVO PER FS'!$E:$I,5,0))) | K12: =IF(ISERROR(IF(B12="","",VLOOKUP($X12,'PROMO MV SVO PER FS'!$E:$I,4,0))),"Gestita con procedura FS da CO",IF(B12="","",VLOOKUP($X12,'PROMO MV SVO PER FS'!$E:$I,4,0))) | T12: FALSE | U12: =IF($T12=TRUE,IF(B12="SUPER Unlimited MONDO","9991790945508228",IF(B12="SUPER Unlimited PRO","9991790945508228",IF(B12="SUPER Smart 200GB","9991790945508228",IF(B12="Super Smart 20GB","9991790945508228",IF($B12="SUPER GIGA UNLIMITED","9991744383690315",IF($B12="SUPER GIGA 70","9991744383690315",IF($B12="SUPER GIGA 30","9991744383690315",IF($B12="M2M Full","9991761657929872")))))))),"") | V12: =IF(U12="","",IF(U12="9991790945508228","SVO - Sconto 100% Una Tantum SUPER - PROMOaVOLUME",IF(U12="9991744383305294","SVO - SCONTO 100% UNA TANTUM PRE - PROMOaVOLUME",IF(U12="9991744383690315","SVO - SCONTO 100% UNA TANTUM POST - PROMOaVOLUME",IF(U12="9991761657929872","SVO - SCONTO 100% UNA TANTUM M2M Full - PROMOaVOLUMEE"))))) | X12: =B12&"-"&D12 -> -
E13: =IF($B13="Super Unlimited",1,IF($B13="Super Unlimited Plus",1,IF($B13="Super Smart 100GB",1,IF($B13="SUPER FLEX",1,IF($B13="SUPER GIGA 70",1,IF($B13="SUPER GIGA UNLIMITED",1,IF($B13="Super Unlimited MONDO",1,IF($B13="Super Unlimited PRO",1,IF($B13="Super Smart 200GB",1,IF($B13="Super Smart 20GB",1,0)))))))))) -> 0 | J13: =IF(ISERROR(IF(B13="","",VLOOKUP($X13,'PROMO MV SVO PER FS'!$E:$I,5,0))),"",IF(B13="","",VLOOKUP($X13,'PROMO MV SVO PER FS'!$E:$I,5,0))) | K13: =IF(ISERROR(IF(B13="","",VLOOKUP($X13,'PROMO MV SVO PER FS'!$E:$I,4,0))),"Gestita con procedura FS da CO",IF(B13="","",VLOOKUP($X13,'PROMO MV SVO PER FS'!$E:$I,4,0))) | T13: FALSE | U13: =IF($T13=TRUE,IF(B13="SUPER Unlimited MONDO","9991790945508228",IF(B13="SUPER Unlimited PRO","9991790945508228",IF(B13="SUPER Smart 200GB","9991790945508228",IF(B13="Super Smart 20GB","9991790945508228",IF($B13="SUPER GIGA UNLIMITED","9991744383690315",IF($B13="SUPER GIGA 70","9991744383690315",IF($B13="SUPER GIGA 30","9991744383690315",IF($B13="M2M Full","9991761657929872")))))))),"") | V13: =IF(U13="","",IF(U13="9991790945508228","SVO - Sconto 100% Una Tantum SUPER - PROMOaVOLUME",IF(U13="9991744383305294","SVO - SCONTO 100% UNA TANTUM PRE - PROMOaVOLUME",IF(U13="9991744383690315","SVO - SCONTO 100% UNA TANTUM POST - PROMOaVOLUME",IF(U13="9991761657929872","SVO - SCONTO 100% UNA TANTUM M2M Full - PROMOaVOLUMEE"))))) | X13: =B13&"-"&D13 -> -
B16: LISTINI PHASE OUT
E17: =IF($B17="Super Unlimited",1,IF($B17="Super Unlimited Plus",1,IF($B17="Super Smart 100GB",1,IF($B17="SUPER FLEX",1,IF($B17="SUPER GIGA 70",1,IF($B17="SUPER GIGA UNLIMITED",1,IF($B17="Super Unlimited MONDO",1,IF($B17="Super Unlimited PRO",1,IF($B17="Super Smart 200GB",1,IF($B17="Super Smart 20GB",1,0)))))))))) -> 0 | J17: =IF(ISERROR(IF(B17="","",VLOOKUP($X17,'PROMO MV SVO PER FS'!$E:$I,5,0))),"",IF(B17="","",VLOOKUP($X17,'PROMO MV SVO PER FS'!$E:$I,5,0))) | K17: =IF(ISERROR(IF(B17="","",VLOOKUP($X17,'PROMO MV SVO PER FS'!$E:$I,4,0))),"Gestita con procedura FS da CO",IF(B17="","",VLOOKUP($X17,'PROMO MV SVO PER FS'!$E:$I,4,0))) | T17: FALSE | U17: =IF($T17=TRUE,IF(B17="Super Unlimited","9991744383305294",IF(B17="Super Unlimited Plus","9991744383305294",IF(B17="SUPER SMART 100","9991744383305294",IF(B17="Super Smart 5","9991744383305294")))),"") | V17: =IF(U17="","",IF(U17="9991744383305294","SVO - SCONTO 100% UNA TANTUM PRE - PROMOaVOLUME",IF(U17="9991744383690315","SVO - SCONTO 100% UNA TANTUM POST - PROMOaVOLUME",IF(U17="9991761657929872","SVO - SCONTO 100% UNA TANTUM M2M Full - PROMOaVOLUMEE")))) | X17: =B17&"-"&D17 -> -
E18: =IF($B18="Super Unlimited",1,IF($B18="Super Unlimited Plus",1,IF($B18="Super Smart 100GB",1,IF($B18="SUPER FLEX",1,IF($B18="SUPER GIGA 70",1,IF($B18="SUPER GIGA UNLIMITED",1,IF($B18="Super Unlimited MONDO",1,IF($B18="Super Unlimited PRO",1,IF($B18="Super Smart 200GB",1,IF($B18="Super Smart 20GB",1,0)))))))))) -> 0 | J18: =IF(ISERROR(IF(B18="","",VLOOKUP($X18,'PROMO MV SVO PER FS'!$E:$I,5,0))),"",IF(B18="","",VLOOKUP($X18,'PROMO MV SVO PER FS'!$E:$I,5,0))) | K18: =IF(ISERROR(IF(B18="","",VLOOKUP($X18,'PROMO MV SVO PER FS'!$E:$I,4,0))),"Gestita con procedura FS da CO",IF(B18="","",VLOOKUP($X18,'PROMO MV SVO PER FS'!$E:$I,4,0))) | T18: FALSE | U18: =IF($T18=TRUE,IF(B18="Super Unlimited","9991744383305294",IF(B18="Super Unlimited Plus","9991744383305294",IF(B18="SUPER SMART 100","9991744383305294",IF(B18="Super Smart 5","9991744383305294")))),"") | V18: =IF(U18="","",IF(U18="9991744383305294","SVO - SCONTO 100% UNA TANTUM PRE - PROMOaVOLUME",IF(U18="9991744383690315","SVO - SCONTO 100% UNA TANTUM POST - PROMOaVOLUME",IF(U18="9991761657929872","SVO - SCONTO 100% UNA TANTUM M2M Full - PROMOaVOLUMEE")))) | X18: =B18&"-"&D18 -> -
E19: =IF($B19="Super Unlimited",1,IF($B19="Super Unlimited Plus",1,IF($B19="Super Smart 100GB",1,IF($B19="SUPER FLEX",1,IF($B19="SUPER GIGA 70",1,IF($B19="SUPER GIGA UNLIMITED",1,IF($B19="Super Unlimited MONDO",1,IF($B19="Super Unlimited PRO",1,IF($B19="Super Smart 200GB",1,IF($B19="Super Smart 20GB",1,0)))))))))) -> 0 | J19: =IF(ISERROR(IF(B19="","",VLOOKUP($X19,'PROMO MV SVO PER FS'!$E:$I,5,0))),"",IF(B19="","",VLOOKUP($X19,'PROMO MV SVO PER FS'!$E:$I,5,0))) | K19: =IF(ISERROR(IF(B19="","",VLOOKUP($X19,'PROMO MV SVO PER FS'!$E:$I,4,0))),"Gestita con procedura FS da CO",IF(B19="","",VLOOKUP($X19,'PROMO MV SVO PER FS'!$E:$I,4,0))) | T19: FALSE | U19: =IF($T19=TRUE,IF(B19="Super Unlimited","9991744383305294",IF(B19="Super Unlimited Plus","9991744383305294",IF(B19="SUPER SMART 100","9991744383305294",IF(B19="Super Smart 5","9991744383305294")))),"") | V19: =IF(U19="","",IF(U19="9991744383305294","SVO - SCONTO 100% UNA TANTUM PRE - PROMOaVOLUME",IF(U19="9991744383690315","SVO - SCONTO 100% UNA TANTUM POST - PROMOaVOLUME",IF(U19="9991761657929872","SVO - SCONTO 100% UNA TANTUM M2M Full - PROMOaVOLUMEE")))) | X19: =B19&"-"&D19 -> -
E20: =IF($B20="Super Unlimited",1,IF($B20="Super Unlimited Plus",1,IF($B20="Super Smart 100GB",1,IF($B20="SUPER FLEX",1,IF($B20="SUPER GIGA 70",1,IF($B20="SUPER GIGA UNLIMITED",1,IF($B20="Super Unlimited MONDO",1,IF($B20="Super Unlimited PRO",1,IF($B20="Super Smart 200GB",1,IF($B20="Super Smart 20GB",1,0)))))))))) -> 0 | J20: =IF(ISERROR(IF(B20="","",VLOOKUP($X20,'PROMO MV SVO PER FS'!$E:$I,5,0))),"",IF(B20="","",VLOOKUP($X20,'PROMO MV SVO PER FS'!$E:$I,5,0))) | K20: =IF(ISERROR(IF(B20="","",VLOOKUP($X20,'PROMO MV SVO PER FS'!$E:$I,4,0))),"Gestita con procedura FS da CO",IF(B20="","",VLOOKUP($X20,'PROMO MV SVO PER FS'!$E:$I,4,0))) | T20: FALSE | U20: =IF($T20=TRUE,IF(B20="Super Unlimited","9991744383305294",IF(B20="Super Unlimited Plus","9991744383305294",IF(B20="SUPER SMART 100","9991744383305294",IF(B20="Super Smart 5","9991744383305294")))),"") | V20: =IF(U20="","",IF(U20="9991744383305294","SVO - SCONTO 100% UNA TANTUM PRE - PROMOaVOLUME",IF(U20="9991744383690315","SVO - SCONTO 100% UNA TANTUM POST - PROMOaVOLUME",IF(U20="9991761657929872","SVO - SCONTO 100% UNA TANTUM M2M Full - PROMOaVOLUMEE")))) | X20: =B20&"-"&D20 -> -
E21: =IF($B21="Super Unlimited",1,IF($B21="Super Unlimited Plus",1,IF($B21="Super Smart 100GB",1,IF($B21="SUPER FLEX",1,IF($B21="SUPER GIGA 70",1,IF($B21="SUPER GIGA UNLIMITED",1,IF($B21="Super Unlimited MONDO",1,IF($B21="Super Unlimited PRO",1,IF($B21="Super Smart 200GB",1,IF($B21="Super Smart 20GB",1,0)))))))))) -> 0 | J21: =IF(ISERROR(IF(B21="","",VLOOKUP($X21,'PROMO MV SVO PER FS'!$E:$I,5,0))),"",IF(B21="","",VLOOKUP($X21,'PROMO MV SVO PER FS'!$E:$I,5,0))) | K21: =IF(ISERROR(IF(B21="","",VLOOKUP($X21,'PROMO MV SVO PER FS'!$E:$I,4,0))),"Gestita con procedura FS da CO",IF(B21="","",VLOOKUP($X21,'PROMO MV SVO PER FS'!$E:$I,4,0))) | T21: FALSE | U21: =IF($T21=TRUE,IF(B21="Super Unlimited","9991744383305294",IF(B21="Super Unlimited Plus","9991744383305294",IF(B21="SUPER SMART 100","9991744383305294",IF(B21="Super Smart 5","9991744383305294")))),"") | V21: =IF(U21="","",IF(U21="9991744383305294","SVO - SCONTO 100% UNA TANTUM PRE - PROMOaVOLUME",IF(U21="9991744383690315","SVO - SCONTO 100% UNA TANTUM POST - PROMOaVOLUME",IF(U21="9991761657929872","SVO - SCONTO 100% UNA TANTUM M2M Full - PROMOaVOLUMEE")))) | X21: =B21&"-"&D21 -> -
E22: =IF($B22="Super Unlimited",1,IF($B22="Super Unlimited Plus",1,IF($B22="Super Smart 100GB",1,IF($B22="SUPER FLEX",1,IF($B22="SUPER GIGA 70",1,IF($B22="SUPER GIGA UNLIMITED",1,IF($B22="Super Unlimited MONDO",1,IF($B22="Super Unlimited PRO",1,IF($B22="Super Smart 200GB",1,IF($B22="Super Smart 20GB",1,0)))))))))) -> 0 | J22: =IF(ISERROR(IF(B22="","",VLOOKUP($X22,'PROMO MV SVO PER FS'!$E:$I,5,0))),"",IF(B22="","",VLOOKUP($X22,'PROMO MV SVO PER FS'!$E:$I,5,0))) | K22: =IF(ISERROR(IF(B22="","",VLOOKUP($X22,'PROMO MV SVO PER FS'!$E:$I,4,0))),"Gestita con procedura FS da CO",IF(B22="","",VLOOKUP($X22,'PROMO MV SVO PER FS'!$E:$I,4,0))) | T22: FALSE | U22: =IF($T22=TRUE,IF(B22="Super Unlimited","9991744383305294",IF(B22="Super Unlimited Plus","9991744383305294",IF(B22="SUPER SMART 100","9991744383305294",IF(B22="Super Smart 5","9991744383305294")))),"") | V22: =IF(U22="","",IF(U22="9991744383305294","SVO - SCONTO 100% UNA TANTUM PRE - PROMOaVOLUME",IF(U22="9991744383690315","SVO - SCONTO 100% UNA TANTUM POST - PROMOaVOLUME",IF(U22="9991761657929872","SVO - SCONTO 100% UNA TANTUM M2M Full - PROMOaVOLUMEE")))) | X22: =B22&"-"&D22 -> -
E23: =IF($B23="Super Unlimited",1,IF($B23="Super Unlimited Plus",1,IF($B23="Super Smart 100GB",1,IF($B23="SUPER FLEX",1,IF($B23="SUPER GIGA 70",1,IF($B23="SUPER GIGA UNLIMITED",1,IF($B23="Super Unlimited MONDO",1,IF($B23="Super Unlimited PRO",1,IF($B23="Super Smart 200GB",1,IF($B23="Super Smart 20GB",1,0)))))))))) -> 0 | J23: =IF(ISERROR(IF(B23="","",VLOOKUP($X23,'PROMO MV SVO PER FS'!$E:$I,5,0))),"",IF(B23="","",VLOOKUP($X23,'PROMO MV SVO PER FS'!$E:$I,5,0))) | K23: =IF(ISERROR(IF(B23="","",VLOOKUP($X23,'PROMO MV SVO PER FS'!$E:$I,4,0))),"Gestita con procedura FS da CO",IF(B23="","",VLOOKUP($X23,'PROMO MV SVO PER FS'!$E:$I,4,0))) | T23: FALSE | U23: =IF($T23=TRUE,IF(B23="Super Unlimited","9991744383305294",IF(B23="Super Unlimited Plus","9991744383305294",IF(B23="SUPER SMART 100","9991744383305294",IF(B23="Super Smart 5","9991744383305294")))),"") | V23: =IF(U23="","",IF(U23="9991744383305294","SVO - SCONTO 100% UNA TANTUM PRE - PROMOaVOLUME",IF(U23="9991744383690315","SVO - SCONTO 100% UNA TANTUM POST - PROMOaVOLUME",IF(U23="9991761657929872","SVO - SCONTO 100% UNA TANTUM M2M Full - PROMOaVOLUMEE")))) | X23: =B23&"-"&D23 -> -
E24: =IF($B24="Super Unlimited",1,IF($B24="Super Unlimited Plus",1,IF($B24="Super Smart 100GB",1,IF($B24="SUPER FLEX",1,IF($B24="SUPER GIGA 70",1,IF($B24="SUPER GIGA UNLIMITED",1,IF($B24="Super Unlimited MONDO",1,IF($B24="Super Unlimited PRO",1,IF($B24="Super Smart 200GB",1,IF($B24="Super Smart 20GB",1,0)))))))))) -> 0 | J24: =IF(ISERROR(IF(B24="","",VLOOKUP($X24,'PROMO MV SVO PER FS'!$E:$I,5,0))),"",IF(B24="","",VLOOKUP($X24,'PROMO MV SVO PER FS'!$E:$I,5,0))) | K24: =IF(ISERROR(IF(B24="","",VLOOKUP($X24,'PROMO MV SVO PER FS'!$E:$I,4,0))),"Gestita con procedura FS da CO",IF(B24="","",VLOOKUP($X24,'PROMO MV SVO PER FS'!$E:$I,4,0))) | T24: FALSE | U24: =IF($T24=TRUE,IF(B24="Super Unlimited","9991744383305294",IF(B24="Super Unlimited Plus","9991744383305294",IF(B24="SUPER SMART 100","9991744383305294",IF(B24="Super Smart 5","9991744383305294")))),"") | V24: =IF(U24="","",IF(U24="9991744383305294","SVO - SCONTO 100% UNA TANTUM PRE - PROMOaVOLUME",IF(U24="9991744383690315","SVO - SCONTO 100% UNA TANTUM POST - PROMOaVOLUME",IF(U24="9991761657929872","SVO - SCONTO 100% UNA TANTUM M2M Full - PROMOaVOLUMEE")))) | X24: =B24&"-"&D24 -> -
E25: =IF($B25="Super Unlimited",1,IF($B25="Super Unlimited Plus",1,IF($B25="Super Smart 100GB",1,IF($B25="SUPER FLEX",1,IF($B25="SUPER GIGA 70",1,IF($B25="SUPER GIGA UNLIMITED",1,IF($B25="Super Unlimited MONDO",1,IF($B25="Super Unlimited PRO",1,IF($B25="Super Smart 200GB",1,IF($B25="Super Smart 20GB",1,0)))))))))) -> 0 | J25: =IF(ISERROR(IF(B25="","",VLOOKUP($X25,'PROMO MV SVO PER FS'!$E:$I,5,0))),"",IF(B25="","",VLOOKUP($X25,'PROMO MV SVO PER FS'!$E:$I,5,0))) | K25: =IF(ISERROR(IF(B25="","",VLOOKUP($X25,'PROMO MV SVO PER FS'!$E:$I,4,0))),"Gestita con procedura FS da CO",IF(B25="","",VLOOKUP($X25,'PROMO MV SVO PER FS'!$E:$I,4,0))) | T25: FALSE | U25: =IF($T25=TRUE,IF(B25="Super Unlimited","9991744383305294",IF(B25="Super Unlimited Plus","9991744383305294",IF(B25="SUPER SMART 100","9991744383305294",IF(B25="Super Smart 5","9991744383305294")))),"") | V25: =IF(U25="","",IF(U25="9991744383305294","SVO - SCONTO 100% UNA TANTUM PRE - PROMOaVOLUME",IF(U25="9991744383690315","SVO - SCONTO 100% UNA TANTUM POST - PROMOaVOLUME",IF(U25="9991761657929872","SVO - SCONTO 100% UNA TANTUM M2M Full - PROMOaVOLUMEE")))) | X25: =B25&"-"&D25 -> -
B28: OPZIONI | C28: N° | D28: Prezzo richiesto (€/mese/cad.)
B37: *** Prezzo al netto della Secure web mobile
B38: Le Offerte Super Unlimited, Super Unlimited Plus, Super Smart 100 e Super Flex, Super GIGA 70, Super GIGA Unlimited prevedono l’opzione Secure Web Mobile sempre abilitata al costo aggiuntivo di 1 €/mese.

Sheet Foglio1
C3: Offerta | D3: Opzioni | E3: MNP | F3: Tipo Richiesta | G3: Terminali | H3: Canale Vendita | I3: Dettaglio TLS
C4: SUPER Unlimited MONDO | D4: Business Travel Dati S | E4: NATIVA | F4: NUOVO CLIENTE | G4: LISTINO | H4: Agenti | I4: CTR Agenzia | J4: SI
C5: SUPER Unlimited PRO | D5: Business Travel Dati M | E5: VODAFONE | F5: AMPLIAMENTO | G5: PROMO MAXI RATA | H5: Agenzia Nazionale | I5: CTR Fornitura | J5: NO
C6: SUPER Smart 200GB | D6: Business Travel Dati L | E6: TIM | F6: AMPLIAMENTO MEDESIME CONDIZIONI | G6: PROMO AD HOC | H6: Agenzia Territoriale
C7: SUPER Smart 20GB | D7: Business Travel Dati Mondo | E7: MVNO | H7: Rewind
C8: SUPER FLEX | D8: Business Travel S | E8: FASTWEB | H8: Energica
C9: SUPER GIGA UNLIMITED | D9: Business Travel M | E9: W3 | H9: Teleseller OUT
C10: SUPER GIGA 30 | D10: Business Travel L | H10: Teleseller IN
C11: SUPER GIGA 70 | D11: Business Travel Mondo
C12: M2M 1GB | D12: Business Travel weekly
C13: M2M 5GB | D13: Business Travel weekly dati
C14: M2M 10GB | D14: GIGA MONDO
C15: M2M 100GB | D15: GIGA MONDO +
C16: M2M 300GB | D16: TOP MONDO
C17: M2M 500GB | D17: MONDO
C18: M2M Full | D18: BUSINESS EVERYWHERE
C19: ALL INCLUSIVE COMPANY | D19: SUPER INTERNATIONAL
D20: INTERNATIONAL AZIENDE
D21: ROAMING PASS
C22: INTERNET 10GB
C23: INTERNET 30GB
B24: PHASE OUT | C24: SMART SHARE 500
B25: PHASE OUT | C25: SMART SHARE UNLIMITED
B26: PHASE OUT | C26: Basket 2GB
B27: PHASE OUT | C27: Basket 10GB
B28: PHASE OUT | C28: Basket 20GB
B29: PHASE OUT | C29: Basket 50GB
B30: PHASE OUT | C30: Basket 100GB
B31: PHASE OUT | C31: Basket 1000GB
B32: PHASE OUT | C32: MY SHARE 5GB
B33: PHASE OUT | C33: MY SHARE 15GB
B34: PHASE OUT | C34: MY SHARE 30GB
B35: PHASE OUT | C35: MY SHARE 60GB
... B51: PHASE OUT non visibili | C51: Leonardo Mega 6000

Sheet PROMO MV SVO PER FS
B2: PROMO MV SVO SUPER UNLIMITED PLUS - solo per ordini FS
B3: OFFERTA | C3: PHX listino | D3: PREZZO SCONTATO | F3: Descrizione Sconto | G3: CONDIZIONI VALIDITA' SCONTO | H3: NOME PROMO | I3: ID PROMO
B4: SUPER Unlimited Plus | C4: PHX70281 | D4: 24.99 | E4: =B4&"-"&D4 -> SUPER Unlimited Plus-24,99 | F4: Promozione 29% SUPER Unlimited Plus | G4: PROMO SVO (visibile con con flag FS) | H4: SVO - SUPER Unlimited Plus SCONTO 10€ - PROMOaVOLUME | I4: 9991770107648797
B5: SUPER Unlimited Plus | C5: PHX70281 | D5: 23.99 | E5: =B5&"-"&D5 -> SUPER Unlimited Plus-23,99 | F5: Promozione 11% SUPER Unlimited Plus + Promozione 20% SUPER Unlimited Plus | G5: PROMO SVO (visibile con con flag FS) | H5: SVO - SUPER Unlimited Plus SCONTO 11€ - PROMOaVOLUME | I5: 9991770108116488
B6: SUPER Unlimited Plus | C6: PHX70281 | D6: 22.99 | E6: =B6&"-"&D6 -> SUPER Unlimited Plus-22,99 | F6: Promozione 34% SUPER Unlimited Plus | G6: PROMO SVO (visibile con con flag FS) | H6: SVO - SUPER Unlimited Plus SCONTO 12€ - PROMOaVOLUME | I6: 9991770108274108
B7: SUPER Unlimited Plus | C7: PHX70281 | D7: 20.99 | E7: =B7&"-"&D7 -> SUPER Unlimited Plus-20,99 | F7: Promozione 29% SUPER Unlimited Plus + Promozione 11% SUPER Unlimited Plus | G7: PROMO SVO (visibile con con flag FS) | H7: SVO - SUPER Unlimited Plus SCONTO 14€ - PROMOaVOLUME | I7: 9991761658420627
B8: SUPER Unlimited Plus | C8: PHX70281 | D8: 19.99 | E8: =B8&"-"&D8 -> SUPER Unlimited Plus-19,99 | F8: Promozione 43% SUPER Unlimited Plus | G8: PROMO SVO (visibile con con flag FS) | H8: SVO - SUPER Unlimited Plus SCONTO 15€ - PROMOaVOLUME | I8: 9991737104817346
B9: SUPER Unlimited Plus | C9: PHX70281 | D9: 18.99 | E9: =B9&"-"&D9 -> SUPER Unlimited Plus-18,99 | F9: Promozione 11% SUPER Unlimited Plus +Promozione 34% SUPER Unlimited Plus | G9: PROMO SVO (visibile con con flag FS) | H9: SVO - SUPER Unlimited Plus SCONTO 16€ - PROMOaVOLUME | I9: 9991737105195779
B11: PROMO MV SVO SUPER UNLIMITED PLUS - solo per ordini FS
B12: OFFERTA | C12: PHX listino | D12: PREZZO SCONTATO | F12: Descrizione Sconto | G12: CONDIZIONI VALIDITA' SCONTO | H12: NOME PROMO | I12: ID PROMO
B13: SUPER Unlimited Mondo | C13: CPQ11586 | D13: 26 | E13: =B13&"-"&D13 -> SUPER Unlimited Mondo-26 | F13: Promo 28% SUPER Unlimited MONDO | G13: PROMO SVO (visibile con con flag FS) | H13: SVO - SUPER Unlimited MONDO SCONTO 10€ - PROMOaVOLUME | I13: 9991790761098504 | J13: NEW
B14: SUPER Unlimited Mondo | C14: CPQ11586 | D14: 25 | E14: =B14&"-"&D14 -> SUPER Unlimited Mondo-25 | F14: Promo 31% SUPER Unlimited MONDO | G14: PROMO SVO (visibile con con flag FS) | H14: SVO - SUPER Unlimited MONDO SCONTO 11€ - PROMOaVOLUME | I14: 9991790761629179 | J14: NEW
B15: SUPER Unlimited Mondo | C15: CPQ11586 | D15: 24 | E15: =B15&"-"&D15 -> SUPER Unlimited Mondo-24 | F15: Promo 33% SUPER Unlimited MONDO | G15: PROMO SVO (visibile con con flag FS) | H15: SVO - SUPER Unlimited MONDO SCONTO 12€ - PROMOaVOLUME | I15: 9991790761718407 | J15: NEW
B16: SUPER Unlimited Mondo | C16: CPQ11586 | D16: 22 | E16: =B16&"-"&D16 -> SUPER Unlimited Mondo-22 | F16: Promo 39% SUPER Unlimited MONDO | G16: PROMO SVO (visibile con con flag FS) | H16: SVO - SUPER Unlimited MONDO SCONTO 14€ - PROMOaVOLUME | I16: 9991790762270425 | J16: NEW
B17: SUPER Unlimited Mondo | C17: CPQ11586 | D17: 21 | E17: =B17&"-"&D17 -> SUPER Unlimited Mondo-21 | F17: Promo 42% SUPER Unlimited MONDO | G17: PROMO SVO (visibile con con flag FS) | H17: SVO - SUPER Unlimited MONDO SCONTO 15€ - PROMOaVOLUME | I17: 9991790762357313 | J17: NEW
B18: SUPER Unlimited Mondo | C18: CPQ11586 | D18: 20 | E18: =B18&"-"&D18 -> SUPER Unlimited Mondo-20 | F18: Promo 44% SUPER Unlimited MONDO | G18: PROMO SVO (visibile con con flag FS) | H18: SVO - SUPER Unlimited MONDO SCONTO 16€ - PROMOaVOLUME | I18: 9991790762424736 | J18: NEW
B20: PROMO MV SUPER UNLIMITED - solo per ordini FS
B21: OFFERTA | C21: PHX listino | D21: PREZZO SCONTATO | F21: Descrizione Sconto | G21: CONDIZIONI VALIDITA' SCONTO | H21: NOME PROMO | I21: ID PROMO
B22: SUPER Unlimited | C22: PHX70087 | D22: 17.99 | E22: =B22&"-"&D22 -> SUPER Unlimited-17,99 | F22: Promozione 28% SUPER Unlimited | G22: PROMO SVO (visibile con con flag FS) | H22: SVO - SUPER Unlimited SCONTO 7€ - PROMOaVOLUME | I22: 9991763715971927
B23: SUPER Unlimited | C23: PHX70087 | D23: 16.99 | E23: =B23&"-"&D23 -> SUPER Unlimited-16,99 | F23: Promozione 12% SUPER Unlimited + Promozione 20% SUPER Unlimited | G23: PROMO SVO (visibile con con flag FS) | H23: SVO - SUPER Unlimited SCONTO 8€ - PROMOaVOLUME | I23: 9991763718825644
B24: SUPER Unlimited | C24: PHX70087 | D24: 15.99 | E24: =B24&"-"&D24 -> SUPER Unlimited-15,99 | F24: Promozione 4% SUPER Unlimited Promozione 12% SUPER Unlimited Promozione 20% SUPER Unlimited | G24: PROMO SVO (visibile con con flag FS) | H24: SVO - SUPER Unlimited SCONTO 9€ - PROMOaVOLUME | I24: 9991763719721210
B25: SUPER Unlimited | C25: PHX70087 | D25: 14.99 | E25: =B25&"-"&D25 -> SUPER Unlimited-14,99 | F25: Promozione 40% SUPER Unlimited | G25: PROMO SVO (visibile con con flag FS) | H25: SVO - SUPER Unlimited SCONTO 10€ - GRANDI AZIENDE | I25: 9991761658121657
B26: SUPER Unlimited | C26: PHX70087 | D26: 13.99 | E26: =B26&"-"&D26 -> SUPER Unlimited-13,99 | F26: Promozione 40% SUPER Unlimited + Promozione 4% SUPER Unlimited | G26: PROMO SVO (visibile con con flag FS) | H26: SVO - SUPER Unlimited SCONTO 11€ - PROMOaVOLUME | I26: 9991763719872655
B27: SUPER Unlimited | C27: PHX70087 | D27: 12.99 | E27: =B27&"-"&D27 -> SUPER Unlimited-12,99 | F27: Promozione 48% SUPER Unlimited | G27: PROMO SVO (visibile con con flag FS) | H27: SVO - SUPER Unlimited SCONTO 12€ - PROMOaVOLUME | I27: 9991763719964172
B28: SUPER Unlimited | C28: PHX70087 | D28: 12 | E28: =B28&"-"&D28 -> SUPER Unlimited-12 | F28: Promozione 48% SUPER Unlimited + Promozione 4% SUPER Unlimited | G28: PROMO SVO (visibile con con flag FS) | H28: SVO - SUPER Unlimited SCONTO 12,99€ - GRANDI AZIENDE | I28: 9991737105503895
B29: SUPER Unlimited | C29: PHX70087 | D29: 11 | E29: =B29&"-"&D29 -> SUPER Unlimited-11 | F29: Promozione 4% SUPER Unlimited+ Promozione 12% SUPER Unlimited +Promozione 40% SUPER Unlimited | G29: PROMO SVO (visibile con con flag FS) | H29: SVO - SUPER Unlimited SCONTO 13,99€ - PROMOaVOLUME | I29: 9991737105764288
B30: SUPER Unlimited | C30: PHX70087 | D30: 10 | E30: =B30&"-"&D30 -> SUPER Unlimited-10 | F30: Promozione 12% SUPER Unlimited+ Promozione 20% SUPER Unlimited +Promozione 28% SUPER Unlimited | G30: PROMO SVO (visibile con con flag FS) | H30: SVO - SUPER Unlimited SCONTO 14,99€ - PROMOaVOLUME | I30: 9991737106438774
B31: SUPER Unlimited | C31: PHX70087 | D31: 9 | E31: =B31&"-"&D31 -> SUPER Unlimited-9 | F31: Promozione 40% SUPER Unlimited + Promozione 20% SUPER Unlimited + Promozione 4% SUPER Unlimited | G31: PROMO SVO (visibile con con flag FS) | H31: SVO - SUPER Unlimited SCONTO 15,99€ - PROMOaVOLUME | I31: 9991737106556342
B32: SUPER Unlimited | C32: PHX70087 | D32: 8 | E32: =B32&"-"&D32 -> SUPER Unlimited-8 | F32: Promozione 28% SUPER Unlimited+ Promozione 40% SUPER Unlimited | G32: PROMO SVO (visibile con con flag FS) | H32: SUPER Unlimited SCONTO 16,99€ - PROMOaVOLUME | I32: 9991744366366368
B34: PROMO MV SUPER UNLIMITED PRO - solo per ordini FS
B35: OFFERTA | C35: PHX listino | D35: PREZZO SCONTATO | F35: Descrizione Sconto | G35: CONDIZIONI VALIDITA' SCONTO | H35: NOME PROMO | I35: ID PROMO
B36: SUPER Unlimited PRO | C36: CPQ11583 | D36: 18 | E36: =B36&"-"&D36 -> SUPER Unlimited PRO-18 | F36: Promo 31% SUPER Unlimited PRO | G36: PROMO SVO (visibile con con flag FS) | H36: SVO - SUPER Unlimited PRO SCONTO 8€ - PROMOaVOLUME | I36: 9991790762945854 | J36: NEW
B37: SUPER Unlimited PRO | C37: CPQ11583 | D37: 17 | E37: =B37&"-"&D37 -> SUPER Unlimited PRO-17 | F37: Promo 35% SUPER Unlimited PRO | G37: PROMO SVO (visibile con con flag FS) | H37: SVO - SUPER Unlimited PRO SCONTO 9€ - PROMOaVOLUME | I37: 9991790766512145 | J37: NEW
B38: SUPER Unlimited PRO | C38: CPQ11583 | D38: 16 | E38: =B38&"-"&D38 -> SUPER Unlimited PRO-16 | F38: Promo 38% SUPER Unlimited PRO | G38: PROMO SVO (visibile con con flag FS) | H38: SVO - SUPER Unlimited PRO SCONTO 10€ - PROMOaVOLUME | I38: 9991790766577810 | J38: NEW
B39: SUPER Unlimited PRO | C39: CPQ11583 | D39: 15 | E39: =B39&"-"&D39 -> SUPER Unlimited PRO-15 | F39: Promo 42% SUPER Unlimited PRO | G39: PROMO SVO (visibile con con flag FS) | H39: SVO - SUPER Unlimited PRO SCONTO 11€ - GRANDI AZIENDE | I39: 9991790766667012 | J39: NEW
B40: SUPER Unlimited PRO | C40: CPQ11583 | D40: 14 | E40: =B40&"-"&D40 -> SUPER Unlimited PRO-14 | F40: Promo 46% SUPER Unlimited PRO | G40: PROMO SVO (visibile con con flag FS) | H40: SVO - SUPER Unlimited PRO SCONTO 12€ - PROMOaVOLUME | I40: 9991790766749336 | J40: NEW
B41: SUPER Unlimited PRO | C41: CPQ11583 | D41: 13 | E41: =B41&"-"&D41 -> SUPER Unlimited PRO-13 | F41: Promo 50% SUPER Unlimited PRO | G41: PROMO SVO (visibile con con flag FS) | H41: SVO - SUPER Unlimited PRO SCONTO 13€ - PROMOaVOLUME | I41: 9991791214287880 | J41: NEW
B42: SUPER Unlimited PRO | C42: CPQ11583 | D42: 12 | E42: =B42&"-"&D42 -> SUPER Unlimited PRO-12 | F42: Promo 54% SUPER Unlimited PRO | G42: PROMO SVO (visibile con con flag FS) | H42: SVO - SUPER Unlimited PRO SCONTO 14€ - GRANDI AZIENDE | I42: 9991790766871313 | J42: NEW
B43: SUPER Unlimited PRO | C43: CPQ11583 | D43: 11 | E43: =B43&"-"&D43 -> SUPER Unlimited PRO-11 | F43: Promo 58% SUPER Unlimited PRO | G43: PROMO SVO (visibile con con flag FS) | H43: SVO - SUPER Unlimited PRO SCONTO 15€ - PROMOaVOLUME | I43: 9991790766931962 | J43: NEW
B44: SUPER Unlimited PRO | C44: CPQ11583 | D44: 10 | E44: =B44&"-"&D44 -> SUPER Unlimited PRO-10 | F44: Promo 62% SUPER Unlimited PRO | G44: PROMO SVO (visibile con con flag FS) | H44: SVO - SUPER Unlimited PRO SCONTO 16€ - PROMOaVOLUME | I44: 9991790766986983 | J44: NEW
...
